<sdf version="1.6">
<model name="robot_car" canonical_link='base_footprint'>
  <static>false</static>
  <link name="base_footprint"></link>
  <link name="base_link">
    <pose relative_to='base_footprint'>0 0 0 0 0 0</pose>
    <visual name='base_link visual'>
      <pose>0 0 0 0 0 0</pose>
      <geometry>
        <cylinder>
          <radius>0.1</radius>
          <length>0.12</length>
        </cylinder>
      </geometry>
      <material>
         <ambient>0.9473065367320066 0.8713671191959567 0.14702726648767014 1</ambient>
         <diffuse>0.9473065367320066 0.8713671191959567 0.14702726648767014 1</diffuse>
         <specular>0.1 0.1 0.1 1</specular>
         <emissive>0 0 0 1</emissive>
       </material>
    </visual>
    <collision name='base_link collision'>
      <pose>0 0 0 0 0 0</pose>
      <geometry>
        <cylinder>
          <radius>0.5</radius>
          <length>1</length>
        </cylinder>
      </geometry>
    </collision>
    <inertial>
      <mass>200</mass>
      <inertia>
        <ixx>66.66666666666666</ixx>
        <ixy>0</ixy>
        <ixz>0</ixz>
        <iyy>100</iyy>
        <iyz>0</iyz>
        <izz>66.66666666666666</izz>
      </inertia>
    </inertial>
  </link>
  <joint name="base_footprint_to_base_link" type="fixed">
    <pose relative_to='base_link'>0 0 0 0 0 0 </pose>
    <parent>base_footprint</parent>
    <child>base_link</child>
  </joint>
  <link name="imu">
    <pose relative_to='base_link'>0 0 0 0 0 0</pose>
    <visual name='imu visual'>
      <pose>0 0 0 0 0 0</pose>
      <geometry>
        <box>
          <size>0.1 0.1 0.1</size>
        </box>
      </geometry>
      <material>
         <ambient>0.9215818562755338 0.11953842797895521 0.08228270712149792 1</ambient>
         <diffuse>0.9215818562755338 0.11953842797895521 0.08228270712149792 1</diffuse>
         <specular>0.1 0.1 0.1 1</specular>
         <emissive>0 0 0 1</emissive>
       </material>
    </visual>
    <collision name='imu collision'>
      <pose>0 0 0 0 0 0</pose>
      <geometry>
        <box>
          <size>0.1 0.1 0.1</size>
        </box>
      </geometry>
    </collision>
    <inertial>
      <mass>1</mass>
      <inertia>
        <ixx>0.16666666666666666</ixx>
        <ixy>0</ixy>
        <ixz>0</ixz>
        <iyy>0.16666666666666666</iyy>
        <iyz>0</iyz>
        <izz>0.16666666666666666</izz>
      </inertia>
    </inertial>

        <sensor name="imu" type="imu">
            <always_on>true</always_on>
            <topic>/imu</topic>
            <update_rate>100</update_rate>
            <imu>
                <angular_velocity>
                    <x>
                        <noise type="gaussian">
                            <mean>0</mean>
                            <stddev>0</stddev>
                        </noise>
                    </x>
                    <y>
                        <noise type="gaussian">
                            <mean>0</mean>
                            <stddev>0</stddev>
                        </noise>
                    </y>
                    <z>
                        <noise type="gaussian">
                            <mean>0</mean>
                            <stddev>0</stddev>
                        </noise>
                    </z>
                </angular_velocity>
                <linear_acceleration>
                    <x>
                        <noise type="gaussian">
                            <mean>0</mean>
                            <stddev>0</stddev>
                        </noise>
                    </x>
                    <y>
                        <noise type="gaussian">
                            <mean>0</mean>
                            <stddev>0</stddev>
                        </noise>
                    </y>
                    <z>
                        <noise type="gaussian">
                            <mean>0</mean>
                            <stddev>0</stddev>
                        </noise>
                    </z>
                </linear_acceleration>
            </imu>
        </sensor>
      </link>
  <joint name="base_link_to_imu" type="fixed">
    <pose relative_to='imu'>0 0 0 0 0 0 </pose>
    <parent>base_link</parent>
    <child>imu</child>
  </joint>
  <link name="camera">
    <pose relative_to='base_link'>0.1 0 0.07 0 0 0</pose>
    <visual name='camera visual'>
      <pose>0 0 0 0 0 0</pose>
      <geometry>
        <box>
          <size>0.02 0.1 0.02</size>
        </box>
      </geometry>
      <material>
         <ambient>0.9215818562755338 0.11953842797895521 0.08228270712149792 1</ambient>
         <diffuse>0.9215818562755338 0.11953842797895521 0.08228270712149792 1</diffuse>
         <specular>0.1 0.1 0.1 1</specular>
         <emissive>0 0 0 1</emissive>
       </material>
    </visual>
    <collision name='camera collision'>
      <pose>0 0 0 0 0 0</pose>
      <geometry>
        <box>
          <size>0.02 0.1 0.02</size>
        </box>
      </geometry>
    </collision>
    <inertial>
      <mass>1</mass>
      <inertia>
        <ixx>0.16666666666666666</ixx>
        <ixy>0</ixy>
        <ixz>0</ixz>
        <iyy>0.16666666666666666</iyy>
        <iyz>0</iyz>
        <izz>0.16666666666666666</izz>
      </inertia>
    </inertial>

            <sensor name="camera_camera" type="rgbd_camera">
                <always_on>true</always_on>
                <visualize>true</visualize>
                <update_rate>100</update_rate>
                <topic>/camera</topic>
                <gz_frame_id>camera</gz_frame_id>
                <camera name="camera_camera">
                    <camera_info_topic>camera/camera_info</camera_info_topic>
                    <horizontal_fov>1.3962634</horizontal_fov>
                    <image>
                        <width>800</width>
                        <height>600</height>
                        <format>R8G8B8</format>
                    </image>
                    <clip>
                        <near>0.1</near>
                        <far>100</far>
                    </clip>
                    <noise>
                        <type>gaussian</type>
                        <mean>0</mean>
                        <stddev>0.007</stddev>
                    </noise>
                </camera>
            </sensor>
          </link>
  <joint name="base_link_to_camera" type="fixed">
    <pose relative_to='camera'>0 0 0 0 0 0 </pose>
    <parent>base_link</parent>
    <child>camera</child>
  </joint>
  <link name="front_chaster">
    <pose relative_to='base_link'>0.06 0 -0.06 0 0 0</pose>
    <visual name='front_chaster visual'>
      <pose>0 0 0 0 0 0</pose>
      <geometry>
        <sphere>
          <radius>0.04</radius>
        </sphere>
      </geometry>
      <material>
         <ambient>1 0.181164244239483 0.04231141061442144 1</ambient>
         <diffuse>1 0.181164244239483 0.04231141061442144 1</diffuse>
         <specular>0.1 0.1 0.1 1</specular>
         <emissive>0 0 0 1</emissive>
       </material>
    </visual>
    <collision name='front_chaster collision'>
      <pose>0 0 0 0 0 0</pose>
      <geometry>
        <sphere>
          <radius>0.04</radius>
        </sphere>
      </geometry>
    </collision>
    <inertial>
      <mass>1</mass>
      <inertia>
        <ixx>0.4</ixx>
        <ixy>0</ixy>
        <ixz>0</ixz>
        <iyy>0.4</iyy>
        <iyz>0</iyz>
        <izz>0.4</izz>
      </inertia>
    </inertial>
  </link>
  <joint name="base_link_to_front_chaster" type="fixed">
    <pose relative_to='front_chaster'>0 0 0 0 0 0 </pose>
    <parent>base_link</parent>
    <child>front_chaster</child>
  </joint>
  <link name="back_chaster">
    <pose relative_to='base_link'>-0.06 0 -0.06 0 0 0</pose>
    <visual name='back_chaster visual'>
      <pose>0 0 0 0 0 0</pose>
      <geometry>
        <sphere>
          <radius>0.04</radius>
        </sphere>
      </geometry>
      <material>
         <ambient>1 0.1878207722902346 0 1</ambient>
         <diffuse>1 0.1878207722902346 0 1</diffuse>
         <specular>0.1 0.1 0.1 1</specular>
         <emissive>0 0 0 1</emissive>
       </material>
    </visual>
    <collision name='back_chaster collision'>
      <pose>0 0 0 0 0 0</pose>
      <geometry>
        <sphere>
          <radius>0.04</radius>
        </sphere>
      </geometry>
    </collision>
    <inertial>
      <mass>1</mass>
      <inertia>
        <ixx>0.4</ixx>
        <ixy>0</ixy>
        <ixz>0</ixz>
        <iyy>0.4</iyy>
        <iyz>0</iyz>
        <izz>0.4</izz>
      </inertia>
    </inertial>
  </link>
  <joint name="base_link_to_back_chaster" type="fixed">
    <pose relative_to='back_chaster'>0 0 0 0 0 0 </pose>
    <parent>base_link</parent>
    <child>back_chaster</child>
  </joint>
  <link name="lidar">
    <pose relative_to='base_link'>0 0 0.15000000000000002 0 0 0</pose>
    <visual name='lidar visual'>
      <pose>0 0 0 0 0 0</pose>
      <geometry>
        <cylinder>
          <radius>0.03</radius>
          <length>0.01</length>
        </cylinder>
      </geometry>
      <material>
         <ambient>0.7156935005005721 0.2541520943200296 0.7230551289161951 1</ambient>
         <diffuse>0.7156935005005721 0.2541520943200296 0.7230551289161951 1</diffuse>
         <specular>0.1 0.1 0.1 1</specular>
         <emissive>0 0 0 1</emissive>
       </material>
    </visual>
    <collision name='lidar collision'>
      <pose>0 0 0 0 0 0</pose>
      <geometry>
        <cylinder>
          <radius>0.03</radius>
          <length>0.01</length>
        </cylinder>
      </geometry>
    </collision>
    <inertial>
      <mass>1</mass>
      <inertia>
        <ixx>0.3333333333333333</ixx>
        <ixy>0</ixy>
        <ixz>0</ixz>
        <iyy>0.5</iyy>
        <iyz>0</iyz>
        <izz>0.3333333333333333</izz>
      </inertia>
    </inertial>

        <sensor name="lidar_lidar" type="gpu_lidar">
            <always_on>true</always_on>
            <visualize>true</visualize>
            <pose>-0.064 0 0.121 0 0 0</pose>
            <topic>scan</topic>
            <gz_frame_id>lidar</gz_frame_id>
            <update_rate>5</update_rate>
            <lidar>
                <scan>
                    <horizontal>
                        <samples>360</samples>
                        <resolution>1</resolution>
                        <min_angle>0</min_angle>
                        <max_angle>6.28</max_angle>
                    </horizontal>
                </scan>
                <range>
                    <min>0.12</min>
                    <max>3.5</max>
                    <resolution>0.015</resolution>
                </range>
                <noise>
                    <type>gaussian</type>
                    <mean>0</mean>
                    <stddev>0.01</stddev>
                </noise>
            </lidar>
        </sensor>
      </link>
  <joint name="base_link_to_lidar" type="fixed">
    <pose relative_to='lidar'>0 0 0 0 0 0 </pose>
    <parent>base_link</parent>
    <child>lidar</child>
  </joint>
  <link name="left_wheel">
    <pose relative_to='base_link'>0 0.15 -0.04880298219344714 -1.5707963267948963 0 0</pose>
    <visual name='left_wheel visual'>
      <pose>0 0 0 0 0 0</pose>
      <geometry>
        <cylinder>
          <radius>0.04</radius>
          <length>0.05</length>
        </cylinder>
      </geometry>
      <material>
         <ambient>0.2746773120495699 0.8713671191959567 0.3712376804636741 1</ambient>
         <diffuse>0.2746773120495699 0.8713671191959567 0.3712376804636741 1</diffuse>
         <specular>0.1 0.1 0.1 1</specular>
         <emissive>0 0 0 1</emissive>
       </material>
    </visual>
    <collision name='left_wheel collision'>
      <pose>0 0 0 0 0 0</pose>
      <surface>
        <friction>
          <ode>
              <mu>0.0</mu>
              <mu2>0.0</mu2>
              <kp>1000000000.0</kp>
              <kd>1.0</kd>
              <fdir1>0 0 0</fdir1>
              <slip1>0.0</slip1>
              <slip2>0.0</slip2>
          </ode>
        </friction>
      </surface>
      <geometry>
        <cylinder>
          <radius>0.04</radius>
          <length>0.05</length>
        </cylinder>
      </geometry>
    </collision>
    <inertial>
      <mass>1</mass>
      <inertia>
        <ixx>0.3333333333333333</ixx>
        <ixy>0</ixy>
        <ixz>0</ixz>
        <iyy>0.5</iyy>
        <iyz>0</iyz>
        <izz>0.3333333333333333</izz>
      </inertia>
    </inertial>
  </link>
  <joint name="base_link_to_left_wheel" type="revolute">
    <pose relative_to='left_wheel'>0 0 0 0 0 0 </pose>
    <parent>base_link</parent>
    <child>left_wheel</child>
    <axis>
        <xyz expressed_in='left_wheel'>0 0 1</xyz>
    </axis>
  </joint>
  <link name="right_wheel">
    <pose relative_to='base_link'>0 -0.15 -0.04880298219344714 -1.5707963267948963 0 0</pose>
    <visual name='right_wheel visual'>
      <pose>0 0 0 0 0 0</pose>
      <geometry>
        <cylinder>
          <radius>0.04</radius>
          <length>0.05</length>
        </cylinder>
      </geometry>
      <material>
         <ambient>0.2746773120495699 0.8713671191959567 0.3712376804636741 1</ambient>
         <diffuse>0.2746773120495699 0.8713671191959567 0.3712376804636741 1</diffuse>
         <specular>0.1 0.1 0.1 1</specular>
         <emissive>0 0 0 1</emissive>
       </material>
    </visual>
    <collision name='right_wheel collision'>
      <pose>0 0 0 0 0 0</pose>
      <surface>
        <friction>
          <ode>
              <mu>0.0</mu>
              <mu2>0.0</mu2>
              <kp>1000000000.0</kp>
              <kd>1.0</kd>
              <fdir1>0 0 0</fdir1>
              <slip1>0.0</slip1>
              <slip2>0.0</slip2>
          </ode>
        </friction>
      </surface>
      <geometry>
        <cylinder>
          <radius>0.04</radius>
          <length>0.05</length>
        </cylinder>
      </geometry>
    </collision>
    <inertial>
      <mass>1</mass>
      <inertia>
        <ixx>0.3333333333333333</ixx>
        <ixy>0</ixy>
        <ixz>0</ixz>
        <iyy>0.5</iyy>
        <iyz>0</iyz>
        <izz>0.3333333333333333</izz>
      </inertia>
    </inertial>
  </link>
  <joint name="base_link_to_right_wheel" type="revolute">
    <pose relative_to='right_wheel'>0 0 0 0 0 0 </pose>
    <parent>base_link</parent>
    <child>right_wheel</child>
    <axis>
        <xyz expressed_in='right_wheel'>0 0 1</xyz>
    </axis>
  </joint>
  <link name="lidar_support">
    <pose relative_to='base_link'>0 0 0.1 0 0 0</pose>
    <visual name='lidar_support visual'>
      <pose>0 0 0 0 0 0</pose>
      <geometry>
        <cylinder>
          <radius>0.01</radius>
          <length>0.1</length>
        </cylinder>
      </geometry>
      <material>
         <ambient>0.04666508633021928 0.08228270712149792 0.4735314961384573 1</ambient>
         <diffuse>0.04666508633021928 0.08228270712149792 0.4735314961384573 1</diffuse>
         <specular>0.1 0.1 0.1 1</specular>
         <emissive>0 0 0 1</emissive>
       </material>
    </visual>
    <collision name='lidar_support collision'>
      <pose>0 0 0 0 0 0</pose>
      <geometry>
        <cylinder>
          <radius>0.5</radius>
          <length>1</length>
        </cylinder>
      </geometry>
    </collision>
    <inertial>
      <mass>1</mass>
      <inertia>
        <ixx>0.3333333333333333</ixx>
        <ixy>0</ixy>
        <ixz>0</ixz>
        <iyy>0.5</iyy>
        <iyz>0</iyz>
        <izz>0.3333333333333333</izz>
      </inertia>
    </inertial>
  </link>
  <joint name="base_link_to_lidar_support" type="fixed">
    <pose relative_to='lidar_support'>0 0 0 0 0 0 </pose>
    <parent>base_link</parent>
    <child>lidar_support</child>
  </joint>
    <plugin name="gz::sim::systems::JointStatePublisher" filename="gz-sim-joint-state-publisher-system">
        <topic>joint_states</topic>
        <joint_name>base_link_to_right_wheel</joint_name>
        <joint_name>base_link_to_left_wheel</joint_name>
    </plugin>
    <plugin filename="gz-sim-diff-drive-system" name="gz::sim::systems::DiffDrive">
      <left_joint>base_link_to_left_wheel</left_joint>
      <right_joint>base_link_to_right_wheel</right_joint>
      <wheel_separation>0.3</wheel_separation>
      <wheel_radius>0.04</wheel_radius>
      <max_linear_acceleration>0.033</max_linear_acceleration>
      <odom_topic>odom</odom_topic>
      <topic>cmd_vel</topic>
      <frame_id>odom</frame_id>
      <child_frame_id>base_footprint</child_frame_id>
      <odom_publisher_frequency>30</odom_publisher_frequency>
      <tf_topic>/tf</tf_topic>
    </plugin>
</model>
</sdf>

