<robot name="robot">
  <link name="base_footprint"></link>
  <joint name="base_joint" type="fixed">
    <parent link="base_footprint" />
    <child link="base_link" />
    <origin xyz="0 0 0" rpy="0 0 0" />
  </joint>
  <link name="base_link">
    <visual>
      <origin xyz="0 0 0" rpy="0 0 0" />
      <geometry>
        <cylinder radius="0.1" length="0.12" />
      </geometry>
      <material name="base_link-material">
        <color rgba="0.9473065367320066 0.8713671191959567 0.14702726648767014 1" />
      </material>
    </visual>
    <collision>
      <origin xyz="0 0 0" rpy="0 0 0" />
      <geometry>
        <cylinder radius="0.5" length="1" />
      </geometry>
    </collision>
    <inertial>
      <origin xyz="0 0 0" rpy="0 0 0" />
      <mass value="200" />
      <inertia ixx="66.66666666666666" ixy="0" ixz="0" iyy="100" iyz="0" izz="66.66666666666666" />
    </inertial>
  </link>
  <joint name="base_link_to_imu" type="fixed">
    <parent link="base_link" />
    <child link="imu" />
    <origin xyz="0 0 0" rpy="0 0 0" />
  </joint>
  <link name="imu">
    <visual>
      <origin xyz="0 0 0" rpy="0 0 0" />
      <geometry>
        <box size="0.1 0.1 0.1" />
      </geometry>
      <material name="imu-material">
        <color rgba="0.9215818562755338 0.11953842797895521 0.08228270712149792 1" />
      </material>
    </visual>
    <collision>
      <origin xyz="0 0 0" rpy="0 0 0" />
      <geometry>
        <box size="0.1 0.1 0.1" />
      </geometry>
    </collision>
    <inertial>
      <origin xyz="0 0 0" rpy="0 0 0" />
      <mass value="1" />
      <inertia ixx="0.16666666666666666" ixy="0" ixz="0" iyy="0.16666666666666666" iyz="0" izz="0.16666666666666666" />
    </inertial>
        <sensor type="imu" name="imu">
            <always_on>true</always_on>
            <update_rate>100</update_rate>
            <origin>0 0 0 0 0 0</origin>
            <imu>
                <noise>
                    <type>gaussian</type>
                    <mean>0</mean>
                    <stddev>0</stddev>
                </noise>
            </imu>
        </sensor>
      </link>
  <joint name="base_link_to_camera" type="fixed">
    <parent link="base_link" />
    <child link="camera" />
    <origin xyz="0.1 0 0.07" rpy="0 0 0" />
  </joint>
  <link name="camera">
    <visual>
      <origin xyz="0 0 0" rpy="0 0 0" />
      <geometry>
        <box size="0.02 0.1 0.02" />
      </geometry>
      <material name="camera-material">
        <color rgba="0.9215818562755338 0.11953842797895521 0.08228270712149792 1" />
      </material>
    </visual>
    <collision>
      <origin xyz="0 0 0" rpy="0 0 0" />
      <geometry>
        <box size="0.02 0.1 0.02" />
      </geometry>
    </collision>
    <inertial>
      <origin xyz="0 0 0" rpy="0 0 0" />
      <mass value="1" />
      <inertia ixx="0.16666666666666666" ixy="0" ixz="0" iyy="0.16666666666666666" iyz="0" izz="0.16666666666666666" />
    </inertial>
        <sensor name="camera" type="camera">
            <always_on>true</always_on>
            <update_rate>100</update_rate>
            <origin>0.1 0 0.07 0 0 0</origin>
            <camera>
                <horizontal_fov>1.3962634</horizontal_fov>
                <image>
                    <width>800</width>
                    <height>600</height>
                    <format>R8G8B8</format>
                </image>
                <clip>
                    <near>0.1</near>
                    <far>100</far>
                </clip>
                <noise>
                    <type>gaussian</type>
                    <mean>0.01</mean>
                </noise>
            </camera>
        </sensor>
      </link>
  <joint name="base_link_to_front_chaster" type="fixed">
    <parent link="base_link" />
    <child link="front_chaster" />
    <origin xyz="0.06 0 -0.06" rpy="0 0 0" />
  </joint>
  <link name="front_chaster">
    <visual>
      <origin xyz="0 0 0" rpy="0 0 0" />
      <geometry>
        <sphere radius="0.04" />
      </geometry>
      <material name="front_chaster-material">
        <color rgba="1 0.181164244239483 0.04231141061442144 1" />
      </material>
    </visual>
    <collision>
      <origin xyz="0 0 0" rpy="0 0 0" />
      <geometry>
        <sphere radius="0.04" />
      </geometry>
    </collision>
    <inertial>
      <origin xyz="0 0 0" rpy="0 0 0" />
      <mass value="1" />
      <inertia ixx="0.4" ixy="0" ixz="0" iyy="0.4" iyz="0" izz="0.4" />
    </inertial>
  </link>
  <joint name="base_link_to_back_chaster" type="fixed">
    <parent link="base_link" />
    <child link="back_chaster" />
    <origin xyz="-0.06 0 -0.06" rpy="0 0 0" />
  </joint>
  <link name="back_chaster">
    <visual>
      <origin xyz="0 0 0" rpy="0 0 0" />
      <geometry>
        <sphere radius="0.04" />
      </geometry>
      <material name="back_chaster-material">
        <color rgba="1 0.1878207722902346 0 1" />
      </material>
    </visual>
    <collision>
      <origin xyz="0 0 0" rpy="0 0 0" />
      <geometry>
        <sphere radius="0.04" />
      </geometry>
    </collision>
    <inertial>
      <origin xyz="0 0 0" rpy="0 0 0" />
      <mass value="1" />
      <inertia ixx="0.4" ixy="0" ixz="0" iyy="0.4" iyz="0" izz="0.4" />
    </inertial>
  </link>
  <joint name="base_link_to_lidar" type="fixed">
    <parent link="base_link" />
    <child link="lidar" />
    <origin xyz="0 0 0.15000000000000002" rpy="0 0 0" />
  </joint>
  <link name="lidar">
    <visual>
      <origin xyz="0 0 0" rpy="0 0 0" />
      <geometry>
        <cylinder radius="0.03" length="0.01" />
      </geometry>
      <material name="lidar-material">
        <color rgba="0.7156935005005721 0.2541520943200296 0.7230551289161951 1" />
      </material>
    </visual>
    <collision>
      <origin xyz="0 0 0" rpy="0 0 0" />
      <geometry>
        <cylinder radius="0.03" length="0.01" />
      </geometry>
    </collision>
    <inertial>
      <origin xyz="0 0 0" rpy="0 0 0" />
      <mass value="1" />
      <inertia ixx="0.3333333333333333" ixy="0" ixz="0" iyy="0.5" iyz="0" izz="0.3333333333333333" />
    </inertial>

        <sensor type="lidar" name="lidar">
            <always_on>true</always_on>
            <update_rate>5</update_rate>
            <origin>0 0 0.15000000000000002 0 0 0</origin>
            <ray>
                <scan>
                    <horizontal>
                        <samples>360</samples>
                        <resolution>1</resolution>
                        <min_angle>0</min_angle>
                        <max_angle>6.28</max_angle>
                    </horizontal>
                    <range>
                        <min>0.12</min>
                        <max>3.5</max>
                        <resolution>0.015</resolution>
                    </range>
                </scan>
                <noise>
                    <type>gaussian</type>
                    <mean>0</mean>
                    <stddev>0.01</stddev>
                </noise>
            </ray>
        </sensor>
      </link>
  <joint name="base_link_to_left_wheel" type="continuous">
    <parent link="base_link" />
    <child link="left_wheel" />
    <origin xyz="0 0.15 -0.04880298219344714" rpy="-1.5707963267948963 0 0" />
    <axis xyz="0 0 1"/>
  </joint>
  <link name="left_wheel">
    <visual>
      <origin xyz="0 0 0" rpy="0 0 0" />
      <geometry>
        <cylinder radius="0.04" length="0.05" />
      </geometry>
      <material name="left_wheel-material">
        <color rgba="0.2746773120495699 0.8713671191959567 0.3712376804636741 1" />
      </material>
    </visual>
    <collision>
      <origin xyz="0 0 0" rpy="0 0 0" />
      <geometry>
        <cylinder radius="0.04" length="0.05" />
      </geometry>
    </collision>
    <inertial>
      <origin xyz="0 0 0" rpy="0 0 0" />
      <mass value="1" />
      <inertia ixx="0.3333333333333333" ixy="0" ixz="0" iyy="0.5" iyz="0" izz="0.3333333333333333" />
    </inertial>
  </link>
  <joint name="base_link_to_right_wheel" type="continuous">
    <parent link="base_link" />
    <child link="right_wheel" />
    <origin xyz="0 -0.15 -0.04880298219344714" rpy="-1.5707963267948963 0 0" />
    <axis xyz="0 0 1"/>
  </joint>
  <link name="right_wheel">
    <visual>
      <origin xyz="0 0 0" rpy="0 0 0" />
      <geometry>
        <cylinder radius="0.04" length="0.05" />
      </geometry>
      <material name="right_wheel-material">
        <color rgba="0.2746773120495699 0.8713671191959567 0.3712376804636741 1" />
      </material>
    </visual>
    <collision>
      <origin xyz="0 0 0" rpy="0 0 0" />
      <geometry>
        <cylinder radius="0.04" length="0.05" />
      </geometry>
    </collision>
    <inertial>
      <origin xyz="0 0 0" rpy="0 0 0" />
      <mass value="1" />
      <inertia ixx="0.3333333333333333" ixy="0" ixz="0" iyy="0.5" iyz="0" izz="0.3333333333333333" />
    </inertial>
  </link>
  <joint name="base_link_to_lidar_support" type="fixed">
    <parent link="base_link" />
    <child link="lidar_support" />
    <origin xyz="0 0 0.1" rpy="0 0 0" />
  </joint>
  <link name="lidar_support">
    <visual>
      <origin xyz="0 0 0" rpy="0 0 0" />
      <geometry>
        <cylinder radius="0.01" length="0.1" />
      </geometry>
      <material name="lidar_support-material">
        <color rgba="0.04666508633021928 0.08228270712149792 0.4735314961384573 1" />
      </material>
    </visual>
    <collision>
      <origin xyz="0 0 0" rpy="0 0 0" />
      <geometry>
        <cylinder radius="0.5" length="1" />
      </geometry>
    </collision>
    <inertial>
      <origin xyz="0 0 0" rpy="0 0 0" />
      <mass value="1" />
      <inertia ixx="0.3333333333333333" ixy="0" ixz="0" iyy="0.5" iyz="0" izz="0.3333333333333333" />
    </inertial>
  </link>
</robot>

